<mujoco model="ur5e">
  <compiler angle="radian" meshdir="assets" autolimits="true"/>

  <option integrator="implicitfast"/>

  <default>
    <default class="ur5e">
      <material specular="0.5" shininess="0.25"/>
      <joint axis="0 1 0" range="-6.28319 6.28319" armature="0.1"/>
      <general dyntype="none" gaintype="fixed" biastype="none" ctrlrange="-150 150" dynprm="1 0 0" gainprm="1 0 0" biasprm="0 0 0"
        forcerange="-150 150"/>
      <default class="size3">
        <default class="size3_limited">
          <joint range="-3.1415 3.1415"/>
          <general ctrlrange="-150 150"/>
        </default>
      </default>
      <default class="size1">
        <general dyntype="none" gaintype="fixed" biastype="none" dynprm="1 0 0" gainprm="1 0 0" biasprm="0 0 0" forcerange="-28 28" ctrlrange="-28 28"/>
      </default>
      <default class="visual">
        <geom type="mesh" contype="0" conaffinity="0" group="2"/>
      </default>
      <default class="collision">
        <geom type="capsule" group="3"/>
        <default class="eef_collision">
          <geom type="cylinder"/>
        </default>
      </default>
      <site size="0.001" rgba="0.5 0.5 0.5 0.3" group="4"/>
    </default>
  </default>


  <asset>
    <material class="ur5e" name="black" rgba="0.033 0.033 0.033 0.8"/>
    <material class="ur5e" name="jointgray" rgba="0.278 0.278 0.278 0.8"/>
    <material class="ur5e" name="linkgray" rgba="0.82 0.82 0.82 0.8"/>
    <material class="ur5e" name="urblue" rgba="0.49 0.678 0.8 0.8"/>
    <material class="ur5e" name="whipcolor" rgba="1 1 1 1"/>

    <mesh file="base_0.obj"/>
    <mesh file="base_1.obj"/>
    <mesh file="shoulder_0.obj"/>
    <mesh file="shoulder_1.obj"/>
    <mesh file="shoulder_2.obj"/>
    <mesh file="upperarm_0.obj"/>
    <mesh file="upperarm_1.obj"/>
    <mesh file="upperarm_2.obj"/>
    <mesh file="upperarm_3.obj"/>
    <mesh file="forearm_0.obj"/>
    <mesh file="forearm_1.obj"/>
    <mesh file="forearm_2.obj"/>
    <mesh file="forearm_3.obj"/>
    <mesh file="wrist1_0.obj"/>
    <mesh file="wrist1_1.obj"/>
    <mesh file="wrist1_2.obj"/>
    <mesh file="wrist2_0.obj"/>
    <mesh file="wrist2_1.obj"/>
    <mesh file="wrist2_2.obj"/>
    <mesh file="wrist3.obj"/>
  </asset>

  <worldbody>
    <light name="spotlight" mode="targetbodycom" target="wrist_2_link" pos="0 -1 2"/>
    <body name="base" quat="1 0 0 1" childclass="ur5e" gravcomp="0">
      <inertial mass="4.0" pos="0 0 0" diaginertia="0.00443333156 0.00443333156 0.0072"/>
      <geom mesh="base_0" material="black" class="visual"/>
      <geom mesh="base_1" material="jointgray" class="visual"/>
      <body name="shoulder_link" pos="0 0 0.163" gravcomp="0">
        <inertial mass="3.7" pos="0 0 0" diaginertia="0.0102675 0.0102675 0.00666"/>
        <joint name="shoulder_pan_joint" class="size3" axis="0 0 1" actuatorgravcomp="false"/>
        <geom mesh="shoulder_0" material="urblue" class="visual"/>
        <geom mesh="shoulder_1" material="black" class="visual"/>
        <geom mesh="shoulder_2" material="jointgray" class="visual"/>
        <geom class="collision" size="0.06 0.06" pos="0 0 -0.04"/>
        <body name="upper_arm_link" pos="0 0.138 0" quat="1 0 1 0" gravcomp="0">
          <inertial mass="8.393" pos="0 0 0.2125" diaginertia="0.133886 0.133886 0.0151074"/>
          <joint name="shoulder_lift_joint" class="size3" actuatorgravcomp="false"/>
          <geom mesh="upperarm_0" material="linkgray" class="visual"/>
          <geom mesh="upperarm_1" material="black" class="visual"/>
          <geom mesh="upperarm_2" material="jointgray" class="visual"/>
          <geom mesh="upperarm_3" material="urblue" class="visual"/>
          <geom class="collision" pos="0 -0.04 0" quat="1 1 0 0" size="0.06 0.06"/>
          <geom class="collision" size="0.05 0.2" pos="0 0 0.2"/>
          <body name="forearm_link" pos="0 -0.131 0.425" gravcomp="0">
            <inertial mass="2.275" pos="0 0 0.196" diaginertia="0.0311796 0.0311796 0.004095"/>
            <joint name="elbow_joint" class="size3_limited" actuatorgravcomp="false"/>
            <geom mesh="forearm_0" material="urblue" class="visual"/>
            <geom mesh="forearm_1" material="linkgray" class="visual"/>
            <geom mesh="forearm_2" material="black" class="visual"/>
            <geom mesh="forearm_3" material="jointgray" class="visual"/>
            <geom class="collision" pos="0 0.08 0" quat="1 1 0 0" size="0.055 0.06"/>
            <geom class="collision" size="0.038 0.19" pos="0 0 0.2"/>
            <body name="wrist_1_link" pos="0 0 0.392" quat="1 0 1 0" gravcomp="0">
              <inertial mass="1.219" pos="0 0.127 0" diaginertia="0.0025599 0.0025599 0.0021942"/>
              <joint name="wrist_1_joint" class="size1" actuatorgravcomp="false"/>
              <geom mesh="wrist1_0" material="black" class="visual"/>
              <geom mesh="wrist1_1" material="urblue" class="visual"/>
              <geom mesh="wrist1_2" material="jointgray" class="visual"/>
              <geom class="collision" pos="0 0.05 0" quat="1 1 0 0" size="0.04 0.07"/>
              <body name="wrist_2_link" pos="0 0.127 0" gravcomp="0">
                <inertial mass="1.219" pos="0 0 0.1" diaginertia="0.0025599 0.0025599 0.0021942"/>
                <joint name="wrist_2_joint" axis="0 0 1" class="size1" actuatorgravcomp="false"/>
                <geom mesh="wrist2_0" material="black" class="visual"/>
                <geom mesh="wrist2_1" material="urblue" class="visual"/>
                <geom mesh="wrist2_2" material="jointgray" class="visual"/>
                <geom class="collision" size="0.04 0.06" pos="0 0 0.04"/>
                <geom class="collision" pos="0 0.02 0.1" quat="1 1 0 0" size="0.04 0.04"/>
                <body name="wrist_3_link" pos="0 0 0.1" gravcomp="0">
                  <inertial mass="0.1889" pos="0 0.0771683 0" quat="1 0 0 1"
                    diaginertia="0.000132134 9.90863e-05 9.90863e-05"/>
                  <joint name="wrist_3_joint" class="size1" actuatorgravcomp="false"/>
                  <geom material="linkgray" mesh="wrist3" class="visual"/>
                  <geom class="eef_collision" pos="0 0.08 0" quat="1 1 0 0" size="0.04 0.02"/>
                  <site name="attachment_site" pos="0 0.1 0" quat="-1 1 0 0"/>
                  <!-- Whip -->
                  <body name="body_whip_node1" euler="1.56 0 0" pos="0 0.10 0">
                    <joint name="joint_whip_node1_X" type="hinge" axis="1  0 0" pos="0 0 0" springref="0" stiffness="0" damping="0" />
                    <joint name="joint_whip_node1_Y" type="hinge" axis="0 -1 0" pos="0 0 0" springref="0" stiffness="0" damping="0" />
                    <geom type="cylinder" fromto="0 0 0 0 0 -0.0720" size="0.0060000" mass="0" />
                    <geom name="geom_whip_node1" type="sphere" material="whipcolor" pos="0 0 -0.0720" size="0.0200000" mass="0.0120000" />
                    <site name="whip_dir" pos="0 0 0" quat="0 1 0 0"/>
                    <body name="body_whip_node2" euler="0 0 0" pos="0 0 -0.0720">
                      <joint name="joint_whip_node2_X" type="hinge" axis="1  0 0" pos="0 0 0" springref="0" stiffness="0.242" damping="0.092" />
                      <joint name="joint_whip_node2_Y" type="hinge" axis="0 -1 0" pos="0 0 0" springref="0" stiffness="0.242" damping="0.092" />
                        <geom type="cylinder" fromto="0 0 0 0 0 -0.0720" size="0.0060000" mass="0" />
                        <geom name="geom_whip_node2" type="sphere" material="whipcolor" pos="0 0 -0.0720" size="0.0200000" mass="0.0120000" />
                        <body name="body_whip_node3" euler="0 0 0" pos="0 0 -0.0720">
                          <joint name="joint_whip_node3_X" type="hinge" axis="1  0 0" pos="0 0 0" springref="0" stiffness="0.242" damping="0.092" />
                          <joint name="joint_whip_node3_Y" type="hinge" axis="0 -1 0" pos="0 0 0" springref="0" stiffness="0.242" damping="0.092" />
                          <geom type="cylinder" fromto="0 0 0 0 0 -0.0720" size="0.0060000" mass="0" />
                          <geom name="geom_whip_node3" type="sphere" material="whipcolor" pos="0 0 -0.0720" size="0.0200000" mass="0.0120000" />
                          <body name="body_whip_node4" euler="0 0 0" pos="0 0 -0.0720">
                            <joint name="joint_whip_node4_X" type="hinge" axis="1  0 0" pos="0 0 0" springref="0" stiffness="0.242" damping="0.092" />
                            <joint name="joint_whip_node4_Y" type="hinge" axis="0 -1 0" pos="0 0 0" springref="0" stiffness="0.242" damping="0.092" />
                              <geom type="cylinder" fromto="0 0 0 0 0 -0.0720" size="0.0060000" mass="0" />
                              <geom name="geom_whip_node4" type="sphere" material="whipcolor" pos="0 0 -0.0720" size="0.0200000" mass="0.0120000" />
                              <body name="body_whip_node5" euler="0 0 0" pos="0 0 -0.0720">
                                <joint name="joint_whip_node5_X" type="hinge" axis="1  0 0" pos="0 0 0" springref="0" stiffness="0.242" damping="0.092" />
                                <joint name="joint_whip_node5_Y" type="hinge" axis="0 -1 0" pos="0 0 0" springref="0" stiffness="0.242" damping="0.092" />
                                <geom type="cylinder" fromto="0 0 0 0 0 -0.0720" size="0.0060000" mass="0" />
                                <geom name="geom_whip_node5" type="sphere" material="whipcolor" pos="0 0 -0.0720" size="0.0200000" mass="0.0120000" />
                                <body name="body_whip_node6" euler="0 0 0" pos="0 0 -0.0720">
                                  <joint name="joint_whip_node6_X" type="hinge" axis="1  0 0" pos="0 0 0" springref="0" stiffness="0.242" damping="0.092" />
                                  <joint name="joint_whip_node6_Y" type="hinge" axis="0 -1 0" pos="0 0 0" springref="0" stiffness="0.242" damping="0.092" />
                                    <geom type="cylinder" fromto="0 0 0 0 0 -0.0720" size="0.0060000" mass="0" />
                                    <geom name="geom_whip_node6" type="sphere" material="whipcolor" pos="0 0 -0.0720" size="0.0200000" mass="0.0120000" />
                                    <body name="body_whip_node7" euler="0 0 0" pos="0 0 -0.0720">
                                      <joint name="joint_whip_node7_X" type="hinge" axis="1  0 0" pos="0 0 0" springref="0" stiffness="0.242" damping="0.092" />                              
                                      <joint name="joint_whip_node7_Y" type="hinge" axis="0 -1 0" pos="0 0 0" springref="0" stiffness="0.242" damping="0.092" />
                                      <geom type="cylinder" fromto="0 0 0 0 0 -0.0720" size="0.0060000" mass="0" />
                                      <geom name="geom_whip_node7" type="sphere" material="whipcolor" pos="0 0 -0.0720" size="0.0200000" mass="0.0120000" />
                                      <body name="body_whip_node8" euler="0 0 0" pos="0 0 -0.0720">
                                        <joint name="joint_whip_node8_X" type="hinge" axis="1  0 0" pos="0 0 0" springref="0" stiffness="0.242" damping="0.092" />                                                               
                                        <joint name="joint_whip_node8_Y" type="hinge" axis="0 -1 0" pos="0 0 0" springref="0" stiffness="0.242" damping="0.092" />
                                          <geom type="cylinder" fromto="0 0 0 0 0 -0.0720" size="0.0060000" mass="0" />
                                          <geom name="geom_whip_node8" type="sphere" material="whipcolor" pos="0 0 -0.0720" size="0.0200000" mass="0.0120000" />
                                          <body name="body_whip_node9" euler="0 0 0" pos="0 0 -0.0720">
                                            <joint name="joint_whip_node9_X" type="hinge" axis="1  0 0" pos="0 0 0" springref="0" stiffness="0.242" damping="0.092" />                                                               
                                            <joint name="joint_whip_node9_Y" type="hinge" axis="0 -1 0" pos="0 0 0" springref="0" stiffness="0.242" damping="0.092" />
                                            <geom type="cylinder" fromto="0 0 0 0 0 -0.0720" size="0.0060000" mass="0" />
                                            <geom name="geom_whip_node9" type="sphere" material="whipcolor" pos="0 0 -0.0720" size="0.0200000" mass="0.0120000" />
                                            <body name="body_whip_node10" euler="0 0 0" pos="0 0 -0.0720">
                                              <joint name="joint_whip_node10_X" type="hinge" axis="1  0 0" pos="0 0 0" springref="0" stiffness="0.242" damping="0.092" />                                                                                                      
                                              <joint name="joint_whip_node10_Y" type="hinge" axis="0 -1 0" pos="0 0 0" springref="0" stiffness="0.242" damping="0.092" />
                                                <geom type="cylinder" fromto="0 0 0 0 0 -0.0720" size="0.0060000" mass="0" />
                                                <geom name="geom_whip_node10" type="sphere" material="whipcolor" pos="0 0 -0.0720" size="0.0200000" mass="0.0120000" />
                                                <body name="body_whip_node11" euler="0 0 0" pos="0 0 -0.0720">
                                                  <joint name="joint_whip_node11_X" type="hinge" axis="1  0 0" pos="0 0 0" springref="0" stiffness="0.242" damping="0.092" />                                                                                                      
                                                  <joint name="joint_whip_node11_Y" type="hinge" axis="0 -1 0" pos="0 0 0" springref="0" stiffness="0.242" damping="0.092" />
                                                  <geom type="cylinder" fromto="0 0 0 0 0 -0.0720" size="0.0060000" mass="0" />
                                                  <geom name="geom_whip_node11" type="sphere" material="whipcolor" pos="0 0 -0.0720" size="0.0200000" mass="0.0120000" />
                                                  <body name="body_whip_node12" euler="0 0 0" pos="0 0 -0.0720">
                                                    <joint name="joint_whip_node12_X" type="hinge" axis="1  0 0" pos="0 0 0" springref="0" stiffness="0.242" damping="0.092" />                                                                                                                                                   
                                                    <joint name="joint_whip_node12_Y" type="hinge" axis="0 -1 0" pos="0 0 0" springref="0" stiffness="0.242" damping="0.092" />
                                                      <geom type="cylinder" fromto="0 0 0 0 0 -0.0720" size="0.0060000" mass="0" />
                                                      <geom name="geom_whip_node12" type="sphere" material="whipcolor" pos="0 0 -0.0720" size="0.0200000" mass="0.0120000" />
                                                      <body name="body_whip_node13" euler="0 0 0" pos="0 0 -0.0720">
                                                        <joint name="joint_whip_node13_X" type="hinge" axis="1  0 0" pos="0 0 0" springref="0" stiffness="0.242" damping="0.092" />                                                                                                                                                                                                   
                                                        <joint name="joint_whip_node13_Y" type="hinge" axis="0 -1 0" pos="0 0 0" springref="0" stiffness="0.242" damping="0.092" />
                                                        <geom type="cylinder" fromto="0 0 0 0 0 -0.0720" size="0.0060000" mass="0" />
                                                        <geom name="geom_whip_node13" type="sphere" material="whipcolor" pos="0 0 -0.0720" size="0.0200000" mass="0.0120000" />
                                                        <body name="body_whip_node14" euler="0 0 0" pos="0 0 -0.0720">
                                                          <joint name="joint_whip_node14_X" type="hinge" axis="1  0 0" pos="0 0 0" springref="0" stiffness="0.242" damping="0.092" />                                                                                                                                                                                                   
                                                          <joint name="joint_whip_node14_Y" type="hinge" axis="0 -1 0" pos="0 0 0" springref="0" stiffness="0.242" damping="0.092" />
                                                            <geom type="cylinder" fromto="0 0 0 0 0 -0.0720" size="0.0060000" mass="0" />
                                                            <geom name="geom_whip_node14" type="sphere" material="whipcolor" pos="0 0 -0.0720" size="0.0200000" mass="0.0120000" />
                                                            <body name="body_whip_node15" euler="0 0 0" pos="0 0 -0.0720">
                                                              <joint name="joint_whip_node15_X" type="hinge" axis="1  0 0" pos="0 0 0" springref="0" stiffness="0.242" damping="0.092" />                                                                                                                                                                                                   
                                                              <joint name="joint_whip_node15_Y" type="hinge" axis="0 -1 0" pos="0 0 0" springref="0" stiffness="0.242" damping="0.092" />
                                                              <geom type="cylinder" fromto="0 0 0 0 0 -0.0720" size="0.0060000" mass="0" />
                                                              <geom name="geom_whip_node15" type="sphere" material="whipcolor" pos="0 0 -0.0720" size="0.0200000" mass="0.0120000" />
                                                              <body name="body_whip_node16" euler="0 0 0" pos="0 0 -0.0720">
                                                                <joint name="joint_whip_node16_X" type="hinge" axis="1  0 0" pos="0 0 0" springref="0" stiffness="0.242" damping="0.092" />                                                                                                                                                                                                   
                                                                <joint name="joint_whip_node16_Y" type="hinge" axis="0 -1 0" pos="0 0 0" springref="0" stiffness="0.242" damping="0.092" />
                                                                  <geom type="cylinder" fromto="0 0 0 0 0 -0.0720" size="0.0060000" mass="0" />
                                                                  <geom name="geom_whip_node16" type="sphere" material="whipcolor" pos="0 0 -0.0720" size="0.0200000" mass="0.0120000" />
                                                                  <body name="body_whip_node17" euler="0 0 0" pos="0 0 -0.0720">
                                                                    <joint name="joint_whip_node17_X" type="hinge" axis="1  0 0" pos="0 0 0" springref="0" stiffness="0.242" damping="0.092" />                                                                                                                                                                                                                                                               
                                                                    <joint name="joint_whip_node17_Y" type="hinge" axis="0 -1 0" pos="0 0 0" springref="0" stiffness="0.242" damping="0.092" />
                                                                    <geom type="cylinder" fromto="0 0 0 0 0 -0.0720" size="0.0060000" mass="0" />
                                                                    <geom name="geom_whip_node17" type="sphere" material="whipcolor" pos="0 0 -0.0720" size="0.0200000" mass="0.0120000" />
                                                                    <body name="body_whip_node18" euler="0 0 0" pos="0 0 -0.0720">
                                                                      <joint name="joint_whip_node18_X" type="hinge" axis="1  0 0" pos="0 0 0" springref="0" stiffness="0.242" damping="0.092" />                                                                                                                                                                                                                                                               
                                                                      <joint name="joint_whip_node18_Y" type="hinge" axis="0 -1 0" pos="0 0 0" springref="0" stiffness="0.242" damping="0.092" />
                                                                        <geom type="cylinder" fromto="0 0 0 0 0 -0.0720" size="0.0060000" mass="0" />
                                                                        <geom name="geom_whip_node18" type="sphere" material="whipcolor" pos="0 0 -0.0720" size="0.0200000" mass="0.0120000" />
                                                                        <body name="body_whip_node19" euler="0 0 0" pos="0 0 -0.0720">
                                                                          <joint name="joint_whip_node19_X" type="hinge" axis="1  0 0" pos="0 0 0" springref="0" stiffness="0.242" damping="0.092" />                                                                                                                                                                                                                                                               
                                                                          <joint name="joint_whip_node19_Y" type="hinge" axis="0 -1 0" pos="0 0 0" springref="0" stiffness="0.242" damping="0.092" />
                                                                          <geom type="cylinder" fromto="0 0 0 0 0 -0.0720" size="0.0060000" mass="0" />
                                                                          <geom name="geom_whip_node19" type="sphere" material="whipcolor" pos="0 0 -0.0720" size="0.0200000" mass="0.0120000" />
                                                                          <body name="body_whip_node20" euler="0 0 0" pos="0 0 -0.0720">
                                                                            <joint name="joint_whip_node20_X" type="hinge" axis="1  0 0" pos="0 0 0" springref="0" stiffness="0.242" damping="0.092" />                                                                                                                                                                                                                                                                                                                                    
                                                                            <joint name="joint_whip_node20_Y" type="hinge" axis="0 -1 0" pos="0 0 0" springref="0" stiffness="0.242" damping="0.092" />
                                                                              <geom type="cylinder" fromto="0 0 0 0 0 -0.0720" size="0.0060000" mass="0" />
                                                                              <geom name="geom_whip_node20" type="sphere" material="whipcolor" pos="0 0 -0.0720" size="0.0200000" mass="0.0120000" />
                                                                              <body name="body_whip_node21" euler="0 0 0" pos="0 0 -0.0720">
                                                                                <joint name="joint_whip_node21_X" type="hinge" axis="1  0 0" pos="0 0 0" springref="0" stiffness="0.242" damping="0.092" />                                                                                                                                                                                                                                                                                                                                    
                                                                                <joint name="joint_whip_node21_Y" type="hinge" axis="0 -1 0" pos="0 0 0" springref="0" stiffness="0.242" damping="0.092" />
                                                                                <geom type="cylinder" fromto="0 0 0 0 0 -0.0720" size="0.0060000" mass="0" />
                                                                                <geom name="geom_whip_node21" type="sphere" material="whipcolor" pos="0 0 -0.0720" size="0.0200000" mass="0.0120000" />
                                                                                <body name="body_whip_node22" euler="0 0 0" pos="0 0 -0.0720">
                                                                                  <joint name="joint_whip_node22_X" type="hinge" axis="1  0 0" pos="0 0 0" springref="0" stiffness="0.242" damping="0.092" />                                                                                                                                                                                                                                                                                                                                                                                                               
                                                                                  <joint name="joint_whip_node22_Y" type="hinge" axis="0 -1 0" pos="0 0 0" springref="0" stiffness="0.242" damping="0.092" />
                                                                                    <geom type="cylinder" fromto="0 0 0 0 0 -0.0720" size="0.0060000" mass="0" />
                                                                                    <geom name="geom_whip_node22" type="sphere" material="whipcolor" pos="0 0 -0.0720" size="0.0200000" mass="0.0120000" />
                                                                                    <body name="body_whip_node23" euler="0 0 0" pos="0 0 -0.0720">
                                                                                      <joint name="joint_whip_node23_X" type="hinge" axis="1  0 0" pos="0 0 0" springref="0" stiffness="0.242" damping="0.092" />                                                                                                                                                                                                                                                                                                                                                                                                               
                                                                                      <joint name="joint_whip_node23_Y" type="hinge" axis="0 -1 0" pos="0 0 0" springref="0" stiffness="0.242" damping="0.092" />
                                                                                      <geom type="cylinder" fromto="0 0 0 0 0 -0.0720" size="0.0060000" mass="0" />
                                                                                      <geom name="geom_whip_node23" type="sphere" material="whipcolor" pos="0 0 -0.0720" size="0.0200000" mass="0.0120000" />
                                                                                      <body name="body_whip_node24" euler="0 0 0" pos="0 0 -0.0720">
                                                                                        <joint name="joint_whip_node24_X" type="hinge" axis="1  0 0" pos="0 0 0" springref="0" stiffness="0.242" damping="0.092" />                                                                                                                                                                                                                                                                                                                                                                                                                                                                                                
                                                                                        <joint name="joint_whip_node24_Y" type="hinge" axis="0 -1 0" pos="0 0 0" springref="0" stiffness="0.242" damping="0.092" />
                                                                                          <geom type="cylinder" fromto="0 0 0 0 0 -0.0720" size="0.0060000" mass="0" />
                                                                                          <geom name="geom_whip_node24" type="sphere" material="whipcolor" pos="0 0 -0.0720" size="0.0200000" mass="0.0120000" />
                                                                                          <body name="body_whip_node25" euler="0 0 0" pos="0 0 -0.0720">
                                                                                            <joint name="joint_whip_node25_X" type="hinge" axis="1  0 0" pos="0 0 0" springref="0" stiffness="0.242" damping="0.092" />                                                                                                                                                                                                                                                                                                                                                                                                                                                                                                
                                                                                            <joint name="joint_whip_node25_Y" type="hinge" axis="0 -1 0" pos="0 0 0" springref="0" stiffness="0.242" damping="0.092" />
                                                                                            <geom type="cylinder" fromto="0 0 0 0 0 -0.0720" size="0.0060000" mass="0" />
                                                                                            <geom name="geom_whip_node25" type="sphere" material="whipcolor" pos="0 0 -0.0720" size="0.0200000" mass="0.0120000" />
                                                                                            <site name='site_whip_tip' pos='0 0 -0.0720' /> 
                                                                                          </body>
                                                                                      </body>
                                                                                    </body>
                                                                                </body>
                                                                              </body>
                                                                          </body>
                                                                        </body>
                                                                    </body>
                                                                  </body>
                                                              </body>
                                                            </body>
                                                        </body>
                                                      </body>
                                                  </body>
                                                </body>
                                            </body>
                                          </body>
                                      </body>
                                    </body>
                                </body>
                              </body>
                          </body>
                        </body>
                    </body>
                  </body>

                </body>
              </body>
            </body>
          </body>
        </body>
      </body>
    </body>
    <body name="target_body" pos="1.9950 0.0000 0.0000" gravcomp="1">
      <joint name="target_joint" type="free"/>
      <geom name="geom_target" type="sphere" size="0.03" rgba="0 0.4470 0.7410 1" mass="0.1" contype="0" conaffinity="0"/>
    </body>

    <geom name="geom_box" type="box" pos="2.0 0.000 0.0000" rgba="0 0.4470 0.7410 0.3" mass="0" size="0.8 0.8 0.8" contype="0" conaffinity="0"/>
    <geom name="x_axis" type="cylinder" fromto="0 0 0 0.5 0 0" size="0.01" mass="0" rgba="1 0 0 1" contype="0" conaffinity="0"/>
    <geom name="y_axis" type="cylinder" fromto="0 0 0 0 0.5 0" size="0.01" mass="0" rgba="0 1 0 1" contype="0" conaffinity="0"/>
    <geom name="z_axis" type="cylinder" fromto="0 0 0 0 0 0.5" size="0.01" mass="0" rgba="0 0 1 1" contype="0" conaffinity="0"/>
  </worldbody>

  <actuator>
    <general class="size3" name="shoulder_pan" joint="shoulder_pan_joint"/>
    <general class="size3" name="shoulder_lift" joint="shoulder_lift_joint"/>
    <general class="size3_limited" name="elbow" joint="elbow_joint"/>
    <general class="size1" name="wrist_1" joint="wrist_1_joint"/>
    <general class="size1" name="wrist_2" joint="wrist_2_joint"/>
    <general class="size1" name="wrist_3" joint="wrist_3_joint"/>
  </actuator>

  <size nuserdata="30"/>
</mujoco>
